Workbook
Name _A65555: #REF!
Name namenlijst: Medewerker!$C$8:$C$107
Name TKWS: #REF!
Name _A65555: #REF!
Name _A65555: #REF!
Name _A65555: #REF!
Name TKWS: Ma!$B$13
Name _A65555: #REF!
Name TKWS: Di!$B$13
Name _A65555: #REF!
Name TKWS: Wo!$B$13
Name _A65555: #REF!
Name TKWS: Do!$B$13
Name _A65555: #REF!
Name TKWS: Vr!$B$13
Name _A65555: #REF!
Name TKWS: Za!$B$13
Name _A65555: #REF!
Name TKWS: Zo!$B$13
Name _A65555: #REF!
Name _A65555: #REF!

Sheet Werkschema - Instelling
E1: Exclusieve Dag | L1: Vaste tijd | S1: Exclusieve Dag Vergeleken | Z1: Volgorde | AA1: Rekentijd
A2: Omschrijving taak | B2: Afkorting | C2: Koppel | D2: Plustijd | E2: Ma | F2: Di | G2: Wo | H2: Do | I2: Vr | J2: Za | K2: Zo | L2: Ma | M2: Di | N2: Wo | O2: Do | P2: Vr | Q2: Za | R2: Zo | S2: Ma | T2: Di | U2: Wo | V2: Do | W2: Vr | X2: Za | Y2: Zo | AA2: Ma | AB2: Naam | AC2: Di | AD2: Naam | AE2: Wo | AF2: Naam | AG2: Do | AH2: Naam | AI2: Vr | AJ2: Naam | AK2: Za | AL2: Naam | AM2: Zo | AN2: Naam | AO2: Taak kopie | AP2: Afkorting kopie
A3: ='Aanpassen Werkschema'!B33 | B3: ='Aanpassen Werkschema'!C33 | C3: =IF('Aanpassen Werkschema'!D33="geplande taak",1,IF('Aanpassen Werkschema'!D33="openingstijd",2,IF('Aanpassen Werkschema'!D33="sluitingstijd",3,IF('Aanpassen Werkschema'!D33="vaste tijd",4,"")))) | D3: ='Aanpassen Werkschema'!E33 | E3: =IF('Aanpassen Werkschema'!F33="v","x","") | F3: =IF('Aanpassen Werkschema'!G33="v","x","") | G3: =IF('Aanpassen Werkschema'!H33="v","x","") | H3: =IF('Aanpassen Werkschema'!I33="v","x","") | I3: =IF('Aanpassen Werkschema'!J33="v","x","") | J3: =IF('Aanpassen Werkschema'!K33="v","x","") | K3: =IF('Aanpassen Werkschema'!L33="v","x","") | L3: =IF('Aanpassen Werkschema'!M33>0,'Aanpassen Werkschema'!M33,"") | M3: =IF('Aanpassen Werkschema'!N33>0,'Aanpassen Werkschema'!N33,"") | N3: =IF('Aanpassen Werkschema'!O33>0,'Aanpassen Werkschema'!O33,"") | O3: =IF('Aanpassen Werkschema'!P33>0,'Aanpassen Werkschema'!P33,"") | P3: =IF('Aanpassen Werkschema'!Q33>0,'Aanpassen Werkschema'!Q33,"") | Q3: =IF('Aanpassen Werkschema'!R33>0,'Aanpassen Werkschema'!R33,"") | R3: =IF('Aanpassen Werkschema'!S33>0,'Aanpassen Werkschema'!S33,"") | S3: =IF('Aanpassen Werkschema'!T33="x","",IF('Aanpassen Werkschema'!N33="v","x",IF(E3="","",IF(E3="x","x")))) | T3: =IF('Aanpassen Werkschema'!U33="x","",IF('Aanpassen Werkschema'!O33="v","x",IF(F3="","",IF(F3="x","x")))) | U3: =IF('Aanpassen Werkschema'!V33="x","",IF('Aanpassen Werkschema'!P33="v","x",IF(G3="","",IF(G3="x","x")))) | V3: =IF('Aanpassen Werkschema'!W33="x","",IF('Aanpassen Werkschema'!Q33="v","x",IF(H3="","",IF(H3="x","x")))) | W3: =IF('Aanpassen Werkschema'!X33="x","",IF('Aanpassen Werkschema'!R33="v","x",IF(I3="","",IF(I3="x","x")))) | X3: =IF('Aanpassen Werkschema'!Y33="x","",IF('Aanpassen Werkschema'!S33="v","x",IF(J3="","",IF(J3="x","x")))) | Y3: =IF('Aanpassen Werkschema'!Z33="x","",IF('Aanpassen Werkschema'!T33="v","x",IF(K3="","",IF(K3="x","x")))) | Z3: 1e-10 | AA3: =IFERROR(IF(C3="",1.1,IF(S3="",1,IF($C3=1,VLOOKUP($B3,'Werkschema - Rekening'!$B$2:$C$46,2,FALSE),IF($C3=2,Instellingen!C$16,IF($C3=3,Instellingen!D$16,IF($C3=4,L3))))+$D3)+$Z3),1.1) | AB3: =IF($B3="","",IFERROR(VLOOKUP($B3,'Werkschema - Rekening'!$B$2:$P$46,3,FALSE),"")) | AC3: =IFERROR(IF(C3="",1.1,IF(T3="",1,IF($C3=1,VLOOKUP($B3,'Werkschema - Rekening'!$B$2:$E$46,4,FALSE),IF($C3=2,Instellingen!E$16,IF($C3=3,Instellingen!F$16,IF($C3=4,M3))))+$D3)+$Z3),1.1) | AD3: =IF($B3="","",IFERROR(VLOOKUP($B3,'Werkschema - Rekening'!$B$2:$P$46,5,FALSE),"")) | AE3: =IFERROR(IF(C3="",1.1,IF(U3="",1,IF($C3=1,VLOOKUP($B3,'Werkschema - Rekening'!$B$2:$G$46,6,FALSE),IF($C3=2,Instellingen!G$16,IF($C3=3,Instellingen!H$16,IF($C3=4,N3))))+$D3)+$Z3),1.1) | AF3: =IF($B3="","",IFERROR(VLOOKUP($B3,'Werkschema - Rekening'!$B$2:$P$46,7,FALSE),"")) | AG3: =IFERROR(IF(C3="",1.1,IF(V3="",1,IF($C3=1,VLOOKUP($B3,'Werkschema - Rekening'!$B$2:$I$46,8,FALSE),IF($C3=2,Instellingen!I$16,IF($C3=3,Instellingen!J$16,IF($C3=4,O3))))+$D3)+$Z3),1.1) | AH3: =IF($B3="","",IFERROR(VLOOKUP($B3,'Werkschema - Rekening'!$B$2:$P$46,9,FALSE),"")) | AI3: =IFERROR(IF(C3="",1.1,IF(W3="",1,IF($C3=1,VLOOKUP($B3,'Werkschema - Rekening'!$B$2:$K$46,10,FALSE),IF($C3=2,Instellingen!K$16,IF($C3=3,Instellingen!L$16,IF($C3=4,P3))))+$D3)+$Z3),1.1) | AJ3: =IF($B3="","",IFERROR(VLOOKUP($B3,'Werkschema - Rekening'!$B$2:$P$46,11,FALSE),"")) | AK3: =IFERROR(IF(C3="",1.1,IF(X3="",1,IF($C3=1,VLOOKUP($B3,'Werkschema - Rekening'!$B$2:$M$46,12,FALSE),IF($C3=2,Instellingen!M$16,IF($C3=3,Instellingen!N$16,IF($C3=4,Q3))))+$D3)+$Z3),1.1) | AL3: =IF($B3="","",IFERROR(VLOOKUP($B3,'Werkschema - Rekening'!$B$2:$P$46,13,FALSE),"")) | AM3: =IFERROR(IF(C3="",1.1,IF(Y3="",1,IF($C3=1,VLOOKUP($B3,'Werkschema - Rekening'!$B$2:$O$46,14,FALSE),IF($C3=2,Instellingen!O$16,IF($C3=3,Instellingen!P$16,IF($C3=4,R3))))+$D3)+$Z3),1.1) | AN3: =IF($B3="","",IFERROR(VLOOKUP($B3,'Werkschema - Rekening'!$B$2:$P$46,15,FALSE),"")) | AO3: =A3 | AP3: =B3
A4: ='Aanpassen Werkschema'!B34 | B4: ='Aanpassen Werkschema'!C34 | C4: =IF('Aanpassen Werkschema'!D34="geplande taak",1,IF('Aanpassen Werkschema'!D34="openingstijd",2,IF('Aanpassen Werkschema'!D34="sluitingstijd",3,IF('Aanpassen Werkschema'!D34="vaste tijd",4,"")))) | D4: ='Aanpassen Werkschema'!E34 | E4: =IF('Aanpassen Werkschema'!F34="v","x","") | F4: =IF('Aanpassen Werkschema'!G34="v","x","") | G4: =IF('Aanpassen Werkschema'!H34="v","x","") | H4: =IF('Aanpassen Werkschema'!I34="v","x","") | I4: =IF('Aanpassen Werkschema'!J34="v","x","") | J4: =IF('Aanpassen Werkschema'!K34="v","x","") | K4: =IF('Aanpassen Werkschema'!L34="v","x","") | L4: =IF('Aanpassen Werkschema'!M34>0,'Aanpassen Werkschema'!M34,"") | M4: =IF('Aanpassen Werkschema'!N34>0,'Aanpassen Werkschema'!N34,"") | N4: =IF('Aanpassen Werkschema'!O34>0,'Aanpassen Werkschema'!O34,"") | O4: =IF('Aanpassen Werkschema'!P34>0,'Aanpassen Werkschema'!P34,"") | P4: =IF('Aanpassen Werkschema'!Q34>0,'Aanpassen Werkschema'!Q34,"") | Q4: =IF('Aanpassen Werkschema'!R34>0,'Aanpassen Werkschema'!R34,"") | R4: =IF('Aanpassen Werkschema'!S34>0,'Aanpassen Werkschema'!S34,"") | S4: =IF('Aanpassen Werkschema'!T34="x","",IF('Aanpassen Werkschema'!N34="v","x",IF(E4="","",IF(E4="x","x")))) | T4: =IF('Aanpassen Werkschema'!U34="x","",IF('Aanpassen Werkschema'!O34="v","x",IF(F4="","",IF(F4="x","x")))) | U4: =IF('Aanpassen Werkschema'!V34="x","",IF('Aanpassen Werkschema'!P34="v","x",IF(G4="","",IF(G4="x","x")))) | V4: =IF('Aanpassen Werkschema'!W34="x","",IF('Aanpassen Werkschema'!Q34="v","x",IF(H4="","",IF(H4="x","x")))) | W4: =IF('Aanpassen Werkschema'!X34="x","",IF('Aanpassen Werkschema'!R34="v","x",IF(I4="","",IF(I4="x","x")))) | X4: =IF('Aanpassen Werkschema'!Y34="x","",IF('Aanpassen Werkschema'!S34="v","x",IF(J4="","",IF(J4="x","x")))) | Y4: =IF('Aanpassen Werkschema'!Z34="x","",IF('Aanpassen Werkschema'!T34="v","x",IF(K4="","",IF(K4="x","x")))) | Z4: =Z3+0.0000000001 | AA4: =IFERROR(IF(C4="",1.1,IF(S4="",1,IF($C4=1,VLOOKUP($B4,'Werkschema - Rekening'!$B$2:$C$46,2,FALSE),IF($C4=2,Instellingen!C$16,IF($C4=3,Instellingen!D$16,IF($C4=4,L4))))+$D4)+$Z4),1.1) | AB4: =IF($B4="","",IFERROR(VLOOKUP($B4,'Werkschema - Rekening'!$B$2:$P$46,3,FALSE),"")) | AC4: =IFERROR(IF(C4="",1.1,IF(T4="",1,IF($C4=1,VLOOKUP($B4,'Werkschema - Rekening'!$B$2:$E$46,4,FALSE),IF($C4=2,Instellingen!E$16,IF($C4=3,Instellingen!F$16,IF($C4=4,M4))))+$D4)+$Z4),1.1) | AD4: =IF($B4="","",IFERROR(VLOOKUP($B4,'Werkschema - Rekening'!$B$2:$P$46,5,FALSE),"")) | AE4: =IFERROR(IF(C4="",1.1,IF(U4="",1,IF($C4=1,VLOOKUP($B4,'Werkschema - Rekening'!$B$2:$G$46,6,FALSE),IF($C4=2,Instellingen!G$16,IF($C4=3,Instellingen!H$16,IF($C4=4,N4))))+$D4)+$Z4),1.1) | AF4: =IF($B4="","",IFERROR(VLOOKUP($B4,'Werkschema - Rekening'!$B$2:$P$46,7,FALSE),"")) | AG4: =IFERROR(IF(C4="",1.1,IF(V4="",1,IF($C4=1,VLOOKUP($B4,'Werkschema - Rekening'!$B$2:$I$46,8,FALSE),IF($C4=2,Instellingen!I$16,IF($C4=3,Instellingen!J$16,IF($C4=4,O4))))+$D4)+$Z4),1.1) | AH4: =IF($B4="","",IFERROR(VLOOKUP($B4,'Werkschema - Rekening'!$B$2:$P$46,9,FALSE),"")) | AI4: =IFERROR(IF(C4="",1.1,IF(W4="",1,IF($C4=1,VLOOKUP($B4,'Werkschema - Rekening'!$B$2:$K$46,10,FALSE),IF($C4=2,Instellingen!K$16,IF($C4=3,Instellingen!L$16,IF($C4=4,P4))))+$D4)+$Z4),1.1) | AJ4: =IF($B4="","",IFERROR(VLOOKUP($B4,'Werkschema - Rekening'!$B$2:$P$46,11,FALSE),"")) | AK4: =IFERROR(IF(C4="",1.1,IF(X4="",1,IF($C4=1,VLOOKUP($B4,'Werkschema - Rekening'!$B$2:$M$46,12,FALSE),IF($C4=2,Instellingen!M$16,IF($C4=3,Instellingen!N$16,IF($C4=4,Q4))))+$D4)+$Z4),1.1) | AL4: =IF($B4="","",IFERROR(VLOOKUP($B4,'Werkschema - Rekening'!$B$2:$P$46,13,FALSE),"")) | AM4: =IFERROR(IF(C4="",1.1,IF(Y4="",1,IF($C4=1,VLOOKUP($B4,'Werkschema - Rekening'!$B$2:$O$46,14,FALSE),IF($C4=2,Instellingen!O$16,IF($C4=3,Instellingen!P$16,IF($C4=4,R4))))+$D4)+$Z4),1.1) | AN4: =IF($B4="","",IFERROR(VLOOKUP($B4,'Werkschema - Rekening'!$B$2:$P$46,15,FALSE),"")) | AO4: =A4 | AP4: =B4
A5: ='Aanpassen Werkschema'!B35 | B5: ='Aanpassen Werkschema'!C35 | C5: =IF('Aanpassen Werkschema'!D35="geplande taak",1,IF('Aanpassen Werkschema'!D35="openingstijd",2,IF('Aanpassen Werkschema'!D35="sluitingstijd",3,IF('Aanpassen Werkschema'!D35="vaste tijd",4,"")))) | D5: ='Aanpassen Werkschema'!E35 | E5: =IF('Aanpassen Werkschema'!F35="v","x","") | F5: =IF('Aanpassen Werkschema'!G35="v","x","") | G5: =IF('Aanpassen Werkschema'!H35="v","x","") | H5: =IF('Aanpassen Werkschema'!I35="v","x","") | I5: =IF('Aanpassen Werkschema'!J35="v","x","") | J5: =IF('Aanpassen Werkschema'!K35="v","x","") | K5: =IF('Aanpassen Werkschema'!L35="v","x","") | L5: =IF('Aanpassen Werkschema'!M35>0,'Aanpassen Werkschema'!M35,"") | M5: =IF('Aanpassen Werkschema'!N35>0,'Aanpassen Werkschema'!N35,"") | N5: =IF('Aanpassen Werkschema'!O35>0,'Aanpassen Werkschema'!O35,"") | O5: =IF('Aanpassen Werkschema'!P35>0,'Aanpassen Werkschema'!P35,"") | P5: =IF('Aanpassen Werkschema'!Q35>0,'Aanpassen Werkschema'!Q35,"") | Q5: =IF('Aanpassen Werkschema'!R35>0,'Aanpassen Werkschema'!R35,"") | R5: =IF('Aanpassen Werkschema'!S35>0,'Aanpassen Werkschema'!S35,"") | S5: =IF('Aanpassen Werkschema'!T35="x","",IF('Aanpassen Werkschema'!N35="v","x",IF(E5="","",IF(E5="x","x")))) | T5: =IF('Aanpassen Werkschema'!U35="x","",IF('Aanpassen Werkschema'!O35="v","x",IF(F5="","",IF(F5="x","x")))) | U5: =IF('Aanpassen Werkschema'!V35="x","",IF('Aanpassen Werkschema'!P35="v","x",IF(G5="","",IF(G5="x","x")))) | V5: =IF('Aanpassen Werkschema'!W35="x","",IF('Aanpassen Werkschema'!Q35="v","x",IF(H5="","",IF(H5="x","x")))) | W5: =IF('Aanpassen Werkschema'!X35="x","",IF('Aanpassen Werkschema'!R35="v","x",IF(I5="","",IF(I5="x","x")))) | X5: =IF('Aanpassen Werkschema'!Y35="x","",IF('Aanpassen Werkschema'!S35="v","x",IF(J5="","",IF(J5="x","x")))) | Y5: =IF('Aanpassen Werkschema'!Z35="x","",IF('Aanpassen Werkschema'!T35="v","x",IF(K5="","",IF(K5="x","x")))) | Z5: =Z4+0.0000000001 | AA5: =IFERROR(IF(C5="",1.1,IF(S5="",1,IF($C5=1,VLOOKUP($B5,'Werkschema - Rekening'!$B$2:$C$46,2,FALSE),IF($C5=2,Instellingen!C$16,IF($C5=3,Instellingen!D$16,IF($C5=4,L5))))+$D5)+$Z5),1.1) | AB5: =IF($B5="","",IFERROR(VLOOKUP($B5,'Werkschema - Rekening'!$B$2:$P$46,3,FALSE),"")) | AC5: =IFERROR(IF(C5="",1.1,IF(T5="",1,IF($C5=1,VLOOKUP($B5,'Werkschema - Rekening'!$B$2:$E$46,4,FALSE),IF($C5=2,Instellingen!E$16,IF($C5=3,Instellingen!F$16,IF($C5=4,M5))))+$D5)+$Z5),1.1) | AD5: =IF($B5="","",IFERROR(VLOOKUP($B5,'Werkschema - Rekening'!$B$2:$P$46,5,FALSE),"")) | AE5: =IFERROR(IF(C5="",1.1,IF(U5="",1,IF($C5=1,VLOOKUP($B5,'Werkschema - Rekening'!$B$2:$G$46,6,FALSE),IF($C5=2,Instellingen!G$16,IF($C5=3,Instellingen!H$16,IF($C5=4,N5))))+$D5)+$Z5),1.1) | AF5: =IF($B5="","",IFERROR(VLOOKUP($B5,'Werkschema - Rekening'!$B$2:$P$46,7,FALSE),"")) | AG5: =IFERROR(IF(C5="",1.1,IF(V5="",1,IF($C5=1,VLOOKUP($B5,'Werkschema - Rekening'!$B$2:$I$46,8,FALSE),IF($C5=2,Instellingen!I$16,IF($C5=3,Instellingen!J$16,IF($C5=4,O5))))+$D5)+$Z5),1.1) | AH5: =IF($B5="","",IFERROR(VLOOKUP($B5,'Werkschema - Rekening'!$B$2:$P$46,9,FALSE),"")) | AI5: =IFERROR(IF(C5="",1.1,IF(W5="",1,IF($C5=1,VLOOKUP($B5,'Werkschema - Rekening'!$B$2:$K$46,10,FALSE),IF($C5=2,Instellingen!K$16,IF($C5=3,Instellingen!L$16,IF($C5=4,P5))))+$D5)+$Z5),1.1) | AJ5: =IF($B5="","",IFERROR(VLOOKUP($B5,'Werkschema - Rekening'!$B$2:$P$46,11,FALSE),"")) | AK5: =IFERROR(IF(C5="",1.1,IF(X5="",1,IF($C5=1,VLOOKUP($B5,'Werkschema - Rekening'!$B$2:$M$46,12,FALSE),IF($C5=2,Instellingen!M$16,IF($C5=3,Instellingen!N$16,IF($C5=4,Q5))))+$D5)+$Z5),1.1) | AL5: =IF($B5="","",IFERROR(VLOOKUP($B5,'Werkschema - Rekening'!$B$2:$P$46,13,FALSE),"")) | AM5: =IFERROR(IF(C5="",1.1,IF(Y5="",1,IF($C5=1,VLOOKUP($B5,'Werkschema - Rekening'!$B$2:$O$46,14,FALSE),IF($C5=2,Instellingen!O$16,IF($C5=3,Instellingen!P$16,IF($C5=4,R5))))+$D5)+$Z5),1.1) | AN5: =IF($B5="","",IFERROR(VLOOKUP($B5,'Werkschema - Rekening'!$B$2:$P$46,15,FALSE),"")) | AO5: =A5 | AP5: =B5
A6: ='Aanpassen Werkschema'!B36 | B6: ='Aanpassen Werkschema'!C36 | C6: =IF('Aanpassen Werkschema'!D36="geplande taak",1,IF('Aanpassen Werkschema'!D36="openingstijd",2,IF('Aanpassen Werkschema'!D36="sluitingstijd",3,IF('Aanpassen Werkschema'!D36="vaste tijd",4,"")))) | D6: ='Aanpassen Werkschema'!E36 | E6: =IF('Aanpassen Werkschema'!F36="v","x","") | F6: =IF('Aanpassen Werkschema'!G36="v","x","") | G6: =IF('Aanpassen Werkschema'!H36="v","x","") | H6: =IF('Aanpassen Werkschema'!I36="v","x","") | I6: =IF('Aanpassen Werkschema'!J36="v","x","") | J6: =IF('Aanpassen Werkschema'!K36="v","x","") | K6: =IF('Aanpassen Werkschema'!L36="v","x","") | L6: =IF('Aanpassen Werkschema'!M36>0,'Aanpassen Werkschema'!M36,"") | M6: =IF('Aanpassen Werkschema'!N36>0,'Aanpassen Werkschema'!N36,"") | N6: =IF('Aanpassen Werkschema'!O36>0,'Aanpassen Werkschema'!O36,"") | O6: =IF('Aanpassen Werkschema'!P36>0,'Aanpassen Werkschema'!P36,"") | P6: =IF('Aanpassen Werkschema'!Q36>0,'Aanpassen Werkschema'!Q36,"") | Q6: =IF('Aanpassen Werkschema'!R36>0,'Aanpassen Werkschema'!R36,"") | R6: =IF('Aanpassen Werkschema'!S36>0,'Aanpassen Werkschema'!S36,"") | S6: =IF('Aanpassen Werkschema'!T36="x","",IF('Aanpassen Werkschema'!N36="v","x",IF(E6="","",IF(E6="x","x")))) | T6: =IF('Aanpassen Werkschema'!U36="x","",IF('Aanpassen Werkschema'!O36="v","x",IF(F6="","",IF(F6="x","x")))) | U6: =IF('Aanpassen Werkschema'!V36="x","",IF('Aanpassen Werkschema'!P36="v","x",IF(G6="","",IF(G6="x","x")))) | V6: =IF('Aanpassen Werkschema'!W36="x","",IF('Aanpassen Werkschema'!Q36="v","x",IF(H6="","",IF(H6="x","x")))) | W6: =IF('Aanpassen Werkschema'!X36="x","",IF('Aanpassen Werkschema'!R36="v","x",IF(I6="","",IF(I6="x","x")))) | X6: =IF('Aanpassen Werkschema'!Y36="x","",IF('Aanpassen Werkschema'!S36="v","x",IF(J6="","",IF(J6="x","x")))) | Y6: =IF('Aanpassen Werkschema'!Z36="x","",IF('Aanpassen Werkschema'!T36="v","x",IF(K6="","",IF(K6="x","x")))) | Z6: =Z5+0.0000000001 | AA6: =IFERROR(IF(C6="",1.1,IF(S6="",1,IF($C6=1,VLOOKUP($B6,'Werkschema - Rekening'!$B$2:$C$46,2,FALSE),IF($C6=2,Instellingen!C$16,IF($C6=3,Instellingen!D$16,IF($C6=4,L6))))+$D6)+$Z6),1.1) | AB6: =IF($B6="","",IFERROR(VLOOKUP($B6,'Werkschema - Rekening'!$B$2:$P$46,3,FALSE),"")) | AC6: =IFERROR(IF(C6="",1.1,IF(T6="",1,IF($C6=1,VLOOKUP($B6,'Werkschema - Rekening'!$B$2:$E$46,4,FALSE),IF($C6=2,Instellingen!E$16,IF($C6=3,Instellingen!F$16,IF($C6=4,M6))))+$D6)+$Z6),1.1) | AD6: =IF($B6="","",IFERROR(VLOOKUP($B6,'Werkschema - Rekening'!$B$2:$P$46,5,FALSE),"")) | AE6: =IFERROR(IF(C6="",1.1,IF(U6="",1,IF($C6=1,VLOOKUP($B6,'Werkschema - Rekening'!$B$2:$G$46,6,FALSE),IF($C6=2,Instellingen!G$16,IF($C6=3,Instellingen!H$16,IF($C6=4,N6))))+$D6)+$Z6),1.1) | AF6: =IF($B6="","",IFERROR(VLOOKUP($B6,'Werkschema - Rekening'!$B$2:$P$46,7,FALSE),"")) | AG6: =IFERROR(IF(C6="",1.1,IF(V6="",1,IF($C6=1,VLOOKUP($B6,'Werkschema - Rekening'!$B$2:$I$46,8,FALSE),IF($C6=2,Instellingen!I$16,IF($C6=3,Instellingen!J$16,IF($C6=4,O6))))+$D6)+$Z6),1.1) | AH6: =IF($B6="","",IFERROR(VLOOKUP($B6,'Werkschema - Rekening'!$B$2:$P$46,9,FALSE),"")) | AI6: =IFERROR(IF(C6="",1.1,IF(W6="",1,IF($C6=1,VLOOKUP($B6,'Werkschema - Rekening'!$B$2:$K$46,10,FALSE),IF($C6=2,Instellingen!K$16,IF($C6=3,Instellingen!L$16,IF($C6=4,P6))))+$D6)+$Z6),1.1) | AJ6: =IF($B6="","",IFERROR(VLOOKUP($B6,'Werkschema - Rekening'!$B$2:$P$46,11,FALSE),"")) | AK6: =IFERROR(IF(C6="",1.1,IF(X6="",1,IF($C6=1,VLOOKUP($B6,'Werkschema - Rekening'!$B$2:$M$46,12,FALSE),IF($C6=2,Instellingen!M$16,IF($C6=3,Instellingen!N$16,IF($C6=4,Q6))))+$D6)+$Z6),1.1) | AL6: =IF($B6="","",IFERROR(VLOOKUP($B6,'Werkschema - Rekening'!$B$2:$P$46,13,FALSE),"")) | AM6: =IFERROR(IF(C6="",1.1,IF(Y6="",1,IF($C6=1,VLOOKUP($B6,'Werkschema - Rekening'!$B$2:$O$46,14,FALSE),IF($C6=2,Instellingen!O$16,IF($C6=3,Instellingen!P$16,IF($C6=4,R6))))+$D6)+$Z6),1.1) | AN6: =IF($B6="","",IFERROR(VLOOKUP($B6,'Werkschema - Rekening'!$B$2:$P$46,15,FALSE),"")) | AO6: =A6 | AP6: =B6
A7: ='Aanpassen Werkschema'!B37 | B7: ='Aanpassen Werkschema'!C37 | C7: =IF('Aanpassen Werkschema'!D37="geplande taak",1,IF('Aanpassen Werkschema'!D37="openingstijd",2,IF('Aanpassen Werkschema'!D37="sluitingstijd",3,IF('Aanpassen Werkschema'!D37="vaste tijd",4,"")))) | D7: ='Aanpassen Werkschema'!E37 | E7: =IF('Aanpassen Werkschema'!F37="v","x","") | F7: =IF('Aanpassen Werkschema'!G37="v","x","") | G7: =IF('Aanpassen Werkschema'!H37="v","x","") | H7: =IF('Aanpassen Werkschema'!I37="v","x","") | I7: =IF('Aanpassen Werkschema'!J37="v","x","") | J7: =IF('Aanpassen Werkschema'!K37="v","x","") | K7: =IF('Aanpassen Werkschema'!L37="v","x","") | L7: =IF('Aanpassen Werkschema'!M37>0,'Aanpassen Werkschema'!M37,"") | M7: =IF('Aanpassen Werkschema'!N37>0,'Aanpassen Werkschema'!N37,"") | N7: =IF('Aanpassen Werkschema'!O37>0,'Aanpassen Werkschema'!O37,"") | O7: =IF('Aanpassen Werkschema'!P37>0,'Aanpassen Werkschema'!P37,"") | P7: =IF('Aanpassen Werkschema'!Q37>0,'Aanpassen Werkschema'!Q37,"") | Q7: =IF('Aanpassen Werkschema'!R37>0,'Aanpassen Werkschema'!R37,"") | R7: =IF('Aanpassen Werkschema'!S37>0,'Aanpassen Werkschema'!S37,"") | S7: =IF('Aanpassen Werkschema'!T37="x","",IF('Aanpassen Werkschema'!N37="v","x",IF(E7="","",IF(E7="x","x")))) | T7: =IF('Aanpassen Werkschema'!U37="x","",IF('Aanpassen Werkschema'!O37="v","x",IF(F7="","",IF(F7="x","x")))) | U7: =IF('Aanpassen Werkschema'!V37="x","",IF('Aanpassen Werkschema'!P37="v","x",IF(G7="","",IF(G7="x","x")))) | V7: =IF('Aanpassen Werkschema'!W37="x","",IF('Aanpassen Werkschema'!Q37="v","x",IF(H7="","",IF(H7="x","x")))) | W7: =IF('Aanpassen Werkschema'!X37="x","",IF('Aanpassen Werkschema'!R37="v","x",IF(I7="","",IF(I7="x","x")))) | X7: =IF('Aanpassen Werkschema'!Y37="x","",IF('Aanpassen Werkschema'!S37="v","x",IF(J7="","",IF(J7="x","x")))) | Y7: =IF('Aanpassen Werkschema'!Z37="x","",IF('Aanpassen Werkschema'!T37="v","x",IF(K7="","",IF(K7="x","x")))) | Z7: =Z6+0.0000000001 | AA7: =IFERROR(IF(C7="",1.1,IF(S7="",1,IF($C7=1,VLOOKUP($B7,'Werkschema - Rekening'!$B$2:$C$46,2,FALSE),IF($C7=2,Instellingen!C$16,IF($C7=3,Instellingen!D$16,IF($C7=4,L7))))+$D7)+$Z7),1.1) | AB7: =IF($B7="","",IFERROR(VLOOKUP($B7,'Werkschema - Rekening'!$B$2:$P$46,3,FALSE),"")) | AC7: =IFERROR(IF(C7="",1.1,IF(T7="",1,IF($C7=1,VLOOKUP($B7,'Werkschema - Rekening'!$B$2:$E$46,4,FALSE),IF($C7=2,Instellingen!E$16,IF($C7=3,Instellingen!F$16,IF($C7=4,M7))))+$D7)+$Z7),1.1) | AD7: =IF($B7="","",IFERROR(VLOOKUP($B7,'Werkschema - Rekening'!$B$2:$P$46,5,FALSE),"")) | AE7: =IFERROR(IF(C7="",1.1,IF(U7="",1,IF($C7=1,VLOOKUP($B7,'Werkschema - Rekening'!$B$2:$G$46,6,FALSE),IF($C7=2,Instellingen!G$16,IF($C7=3,Instellingen!H$16,IF($C7=4,N7))))+$D7)+$Z7),1.1) | AF7: =IF($B7="","",IFERROR(VLOOKUP($B7,'Werkschema - Rekening'!$B$2:$P$46,7,FALSE),"")) | AG7: =IFERROR(IF(C7="",1.1,IF(V7="",1,IF($C7=1,VLOOKUP($B7,'Werkschema - Rekening'!$B$2:$I$46,8,FALSE),IF($C7=2,Instellingen!I$16,IF($C7=3,Instellingen!J$16,IF($C7=4,O7))))+$D7)+$Z7),1.1) | AH7: =IF($B7="","",IFERROR(VLOOKUP($B7,'Werkschema - Rekening'!$B$2:$P$46,9,FALSE),"")) | AI7: =IFERROR(IF(C7="",1.1,IF(W7="",1,IF($C7=1,VLOOKUP($B7,'Werkschema - Rekening'!$B$2:$K$46,10,FALSE),IF($C7=2,Instellingen!K$16,IF($C7=3,Instellingen!L$16,IF($C7=4,P7))))+$D7)+$Z7),1.1) | AJ7: =IF($B7="","",IFERROR(VLOOKUP($B7,'Werkschema - Rekening'!$B$2:$P$46,11,FALSE),"")) | AK7: =IFERROR(IF(C7="",1.1,IF(X7="",1,IF($C7=1,VLOOKUP($B7,'Werkschema - Rekening'!$B$2:$M$46,12,FALSE),IF($C7=2,Instellingen!M$16,IF($C7=3,Instellingen!N$16,IF($C7=4,Q7))))+$D7)+$Z7),1.1) | AL7: =IF($B7="","",IFERROR(VLOOKUP($B7,'Werkschema - Rekening'!$B$2:$P$46,13,FALSE),"")) | AM7: =IFERROR(IF(C7="",1.1,IF(Y7="",1,IF($C7=1,VLOOKUP($B7,'Werkschema - Rekening'!$B$2:$O$46,14,FALSE),IF($C7=2,Instellingen!O$16,IF($C7=3,Instellingen!P$16,IF($C7=4,R7))))+$D7)+$Z7),1.1) | AN7: =IF($B7="","",IFERROR(VLOOKUP($B7,'Werkschema - Rekening'!$B$2:$P$46,15,FALSE),"")) | AO7: =A7 | AP7: =B7
A8: ='Aanpassen Werkschema'!B38 | B8: ='Aanpassen Werkschema'!C38 | C8: =IF('Aanpassen Werkschema'!D38="geplande taak",1,IF('Aanpassen Werkschema'!D38="openingstijd",2,IF('Aanpassen Werkschema'!D38="sluitingstijd",3,IF('Aanpassen Werkschema'!D38="vaste tijd",4,"")))) | D8: ='Aanpassen Werkschema'!E38 | E8: =IF('Aanpassen Werkschema'!F38="v","x","") | F8: =IF('Aanpassen Werkschema'!G38="v","x","") | G8: =IF('Aanpassen Werkschema'!H38="v","x","") | H8: =IF('Aanpassen Werkschema'!I38="v","x","") | I8: =IF('Aanpassen Werkschema'!J38="v","x","") | J8: =IF('Aanpassen Werkschema'!K38="v","x","") | K8: =IF('Aanpassen Werkschema'!L38="v","x","") | L8: =IF('Aanpassen Werkschema'!M38>0,'Aanpassen Werkschema'!M38,"") | M8: =IF('Aanpassen Werkschema'!N38>0,'Aanpassen Werkschema'!N38,"") | N8: =IF('Aanpassen Werkschema'!O38>0,'Aanpassen Werkschema'!O38,"") | O8: =IF('Aanpassen Werkschema'!P38>0,'Aanpassen Werkschema'!P38,"") | P8: =IF('Aanpassen Werkschema'!Q38>0,'Aanpassen Werkschema'!Q38,"") | Q8: =IF('Aanpassen Werkschema'!R38>0,'Aanpassen Werkschema'!R38,"") | R8: =IF('Aanpassen Werkschema'!S38>0,'Aanpassen Werkschema'!S38,"") | S8: =IF('Aanpassen Werkschema'!T38="x","",IF('Aanpassen Werkschema'!N38="v","x",IF(E8="","",IF(E8="x","x")))) | T8: =IF('Aanpassen Werkschema'!U38="x","",IF('Aanpassen Werkschema'!O38="v","x",IF(F8="","",IF(F8="x","x")))) | U8: =IF('Aanpassen Werkschema'!V38="x","",IF('Aanpassen Werkschema'!P38="v","x",IF(G8="","",IF(G8="x","x")))) | V8: =IF('Aanpassen Werkschema'!W38="x","",IF('Aanpassen Werkschema'!Q38="v","x",IF(H8="","",IF(H8="x","x")))) | W8: =IF('Aanpassen Werkschema'!X38="x","",IF('Aanpassen Werkschema'!R38="v","x",IF(I8="","",IF(I8="x","x")))) | X8: =IF('Aanpassen Werkschema'!Y38="x","",IF('Aanpassen Werkschema'!S38="v","x",IF(J8="","",IF(J8="x","x")))) | Y8: =IF('Aanpassen Werkschema'!Z38="x","",IF('Aanpassen Werkschema'!T38="v","x",IF(K8="","",IF(K8="x","x")))) | Z8: =Z7+0.0000000001 | AA8: =IFERROR(IF(C8="",1.1,IF(S8="",1,IF($C8=1,VLOOKUP($B8,'Werkschema - Rekening'!$B$2:$C$46,2,FALSE),IF($C8=2,Instellingen!C$16,IF($C8=3,Instellingen!D$16,IF($C8=4,L8))))+$D8)+$Z8),1.1) | AB8: =IF($B8="","",IFERROR(VLOOKUP($B8,'Werkschema - Rekening'!$B$2:$P$46,3,FALSE),"")) | AC8: =IFERROR(IF(C8="",1.1,IF(T8="",1,IF($C8=1,VLOOKUP($B8,'Werkschema - Rekening'!$B$2:$E$46,4,FALSE),IF($C8=2,Instellingen!E$16,IF($C8=3,Instellingen!F$16,IF($C8=4,M8))))+$D8)+$Z8),1.1) | AD8: =IF($B8="","",IFERROR(VLOOKUP($B8,'Werkschema - Rekening'!$B$2:$P$46,5,FALSE),"")) | AE8: =IFERROR(IF(C8="",1.1,IF(U8="",1,IF($C8=1,VLOOKUP($B8,'Werkschema - Rekening'!$B$2:$G$46,6,FALSE),IF($C8=2,Instellingen!G$16,IF($C8=3,Instellingen!H$16,IF($C8=4,N8))))+$D8)+$Z8),1.1) | AF8: =IF($B8="","",IFERROR(VLOOKUP($B8,'Werkschema - Rekening'!$B$2:$P$46,7,FALSE),"")) | AG8: =IFERROR(IF(C8="",1.1,IF(V8="",1,IF($C8=1,VLOOKUP($B8,'Werkschema - Rekening'!$B$2:$I$46,8,FALSE),IF($C8=2,Instellingen!I$16,IF($C8=3,Instellingen!J$16,IF($C8=4,O8))))+$D8)+$Z8),1.1) | AH8: =IF($B8="","",IFERROR(VLOOKUP($B8,'Werkschema - Rekening'!$B$2:$P$46,9,FALSE),"")) | AI8: =IFERROR(IF(C8="",1.1,IF(W8="",1,IF($C8=1,VLOOKUP($B8,'Werkschema - Rekening'!$B$2:$K$46,10,FALSE),IF($C8=2,Instellingen!K$16,IF($C8=3,Instellingen!L$16,IF($C8=4,P8))))+$D8)+$Z8),1.1) | AJ8: =IF($B8="","",IFERROR(VLOOKUP($B8,'Werkschema - Rekening'!$B$2:$P$46,11,FALSE),"")) | AK8: =IFERROR(IF(C8="",1.1,IF(X8="",1,IF($C8=1,VLOOKUP($B8,'Werkschema - Rekening'!$B$2:$M$46,12,FALSE),IF($C8=2,Instellingen!M$16,IF($C8=3,Instellingen!N$16,IF($C8=4,Q8))))+$D8)+$Z8),1.1) | AL8: =IF($B8="","",IFERROR(VLOOKUP($B8,'Werkschema - Rekening'!$B$2:$P$46,13,FALSE),"")) | AM8: =IFERROR(IF(C8="",1.1,IF(Y8="",1,IF($C8=1,VLOOKUP($B8,'Werkschema - Rekening'!$B$2:$O$46,14,FALSE),IF($C8=2,Instellingen!O$16,IF($C8=3,Instellingen!P$16,IF($C8=4,R8))))+$D8)+$Z8),1.1) | AN8: =IF($B8="","",IFERROR(VLOOKUP($B8,'Werkschema - Rekening'!$B$2:$P$46,15,FALSE),"")) | AO8: =A8 | AP8: =B8
A9: ='Aanpassen Werkschema'!B39 | B9: ='Aanpassen Werkschema'!C39 | C9: =IF('Aanpassen Werkschema'!D39="geplande taak",1,IF('Aanpassen Werkschema'!D39="openingstijd",2,IF('Aanpassen Werkschema'!D39="sluitingstijd",3,IF('Aanpassen Werkschema'!D39="vaste tijd",4,"")))) | D9: ='Aanpassen Werkschema'!E39 | E9: =IF('Aanpassen Werkschema'!F39="v","x","") | F9: =IF('Aanpassen Werkschema'!G39="v","x","") | G9: =IF('Aanpassen Werkschema'!H39="v","x","") | H9: =IF('Aanpassen Werkschema'!I39="v","x","") | I9: =IF('Aanpassen Werkschema'!J39="v","x","") | J9: =IF('Aanpassen Werkschema'!K39="v","x","") | K9: =IF('Aanpassen Werkschema'!L39="v","x","") | L9: =IF('Aanpassen Werkschema'!M39>0,'Aanpassen Werkschema'!M39,"") | M9: =IF('Aanpassen Werkschema'!N39>0,'Aanpassen Werkschema'!N39,"") | N9: =IF('Aanpassen Werkschema'!O39>0,'Aanpassen Werkschema'!O39,"") | O9: =IF('Aanpassen Werkschema'!P39>0,'Aanpassen Werkschema'!P39,"") | P9: =IF('Aanpassen Werkschema'!Q39>0,'Aanpassen Werkschema'!Q39,"") | Q9: =IF('Aanpassen Werkschema'!R39>0,'Aanpassen Werkschema'!R39,"") | R9: =IF('Aanpassen Werkschema'!S39>0,'Aanpassen Werkschema'!S39,"") | S9: =IF('Aanpassen Werkschema'!T39="x","",IF('Aanpassen Werkschema'!N39="v","x",IF(E9="","",IF(E9="x","x")))) | T9: =IF('Aanpassen Werkschema'!U39="x","",IF('Aanpassen Werkschema'!O39="v","x",IF(F9="","",IF(F9="x","x")))) | U9: =IF('Aanpassen Werkschema'!V39="x","",IF('Aanpassen Werkschema'!P39="v","x",IF(G9="","",IF(G9="x","x")))) | V9: =IF('Aanpassen Werkschema'!W39="x","",IF('Aanpassen Werkschema'!Q39="v","x",IF(H9="","",IF(H9="x","x")))) | W9: =IF('Aanpassen Werkschema'!X39="x","",IF('Aanpassen Werkschema'!R39="v","x",IF(I9="","",IF(I9="x","x")))) | X9: =IF('Aanpassen Werkschema'!Y39="x","",IF('Aanpassen Werkschema'!S39="v","x",IF(J9="","",IF(J9="x","x")))) | Y9: =IF('Aanpassen Werkschema'!Z39="x","",IF('Aanpassen Werkschema'!T39="v","x",IF(K9="","",IF(K9="x","x")))) | Z9: =Z8+0.0000000001 | AA9: =IFERROR(IF(C9="",1.1,IF(S9="",1,IF($C9=1,VLOOKUP($B9,'Werkschema - Rekening'!$B$2:$C$46,2,FALSE),IF($C9=2,Instellingen!C$16,IF($C9=3,Instellingen!D$16,IF($C9=4,L9))))+$D9)+$Z9),1.1) | AB9: =IF($B9="","",IFERROR(VLOOKUP($B9,'Werkschema - Rekening'!$B$2:$P$46,3,FALSE),"")) | AC9: =IFERROR(IF(C9="",1.1,IF(T9="",1,IF($C9=1,VLOOKUP($B9,'Werkschema - Rekening'!$B$2:$E$46,4,FALSE),IF($C9=2,Instellingen!E$16,IF($C9=3,Instellingen!F$16,IF($C9=4,M9))))+$D9)+$Z9),1.1) | AD9: =IF($B9="","",IFERROR(VLOOKUP($B9,'Werkschema - Rekening'!$B$2:$P$46,5,FALSE),"")) | AE9: =IFERROR(IF(C9="",1.1,IF(U9="",1,IF($C9=1,VLOOKUP($B9,'Werkschema - Rekening'!$B$2:$G$46,6,FALSE),IF($C9=2,Instellingen!G$16,IF($C9=3,Instellingen!H$16,IF($C9=4,N9))))+$D9)+$Z9),1.1) | AF9: =IF($B9="","",IFERROR(VLOOKUP($B9,'Werkschema - Rekening'!$B$2:$P$46,7,FALSE),"")) | AG9: =IFERROR(IF(C9="",1.1,IF(V9="",1,IF($C9=1,VLOOKUP($B9,'Werkschema - Rekening'!$B$2:$I$46,8,FALSE),IF($C9=2,Instellingen!I$16,IF($C9=3,Instellingen!J$16,IF($C9=4,O9))))+$D9)+$Z9),1.1) | AH9: =IF($B9="","",IFERROR(VLOOKUP($B9,'Werkschema - Rekening'!$B$2:$P$46,9,FALSE),"")) | AI9: =IFERROR(IF(C9="",1.1,IF(W9="",1,IF($C9=1,VLOOKUP($B9,'Werkschema - Rekening'!$B$2:$K$46,10,FALSE),IF($C9=2,Instellingen!K$16,IF($C9=3,Instellingen!L$16,IF($C9=4,P9))))+$D9)+$Z9),1.1) | AJ9: =IF($B9="","",IFERROR(VLOOKUP($B9,'Werkschema - Rekening'!$B$2:$P$46,11,FALSE),"")) | AK9: =IFERROR(IF(C9="",1.1,IF(X9="",1,IF($C9=1,VLOOKUP($B9,'Werkschema - Rekening'!$B$2:$M$46,12,FALSE),IF($C9=2,Instellingen!M$16,IF($C9=3,Instellingen!N$16,IF($C9=4,Q9))))+$D9)+$Z9),1.1) | AL9: =IF($B9="","",IFERROR(VLOOKUP($B9,'Werkschema - Rekening'!$B$2:$P$46,13,FALSE),"")) | AM9: =IFERROR(IF(C9="",1.1,IF(Y9="",1,IF($C9=1,VLOOKUP($B9,'Werkschema - Rekening'!$B$2:$O$46,14,FALSE),IF($C9=2,Instellingen!O$16,IF($C9=3,Instellingen!P$16,IF($C9=4,R9))))+$D9)+$Z9),1.1) | AN9: =IF($B9="","",IFERROR(VLOOKUP($B9,'Werkschema - Rekening'!$B$2:$P$46,15,FALSE),"")) | AO9: =A9 | AP9: =B9
A10: ='Aanpassen Werkschema'!B40 | B10: ='Aanpassen Werkschema'!C40 | C10: =IF('Aanpassen Werkschema'!D40="geplande taak",1,IF('Aanpassen Werkschema'!D40="openingstijd",2,IF('Aanpassen Werkschema'!D40="sluitingstijd",3,IF('Aanpassen Werkschema'!D40="vaste tijd",4,"")))) | D10: ='Aanpassen Werkschema'!E40 | E10: =IF('Aanpassen Werkschema'!F40="v","x","") | F10: =IF('Aanpassen Werkschema'!G40="v","x","") | G10: =IF('Aanpassen Werkschema'!H40="v","x","") | H10: =IF('Aanpassen Werkschema'!I40="v","x","") | I10: =IF('Aanpassen Werkschema'!J40="v","x","") | J10: =IF('Aanpassen Werkschema'!K40="v","x","") | K10: =IF('Aanpassen Werkschema'!L40="v","x","") | L10: =IF('Aanpassen Werkschema'!M40>0,'Aanpassen Werkschema'!M40,"") | M10: =IF('Aanpassen Werkschema'!N40>0,'Aanpassen Werkschema'!N40,"") | N10: =IF('Aanpassen Werkschema'!O40>0,'Aanpassen Werkschema'!O40,"") | O10: =IF('Aanpassen Werkschema'!P40>0,'Aanpassen Werkschema'!P40,"") | P10: =IF('Aanpassen Werkschema'!Q40>0,'Aanpassen Werkschema'!Q40,"") | Q10: =IF('Aanpassen Werkschema'!R40>0,'Aanpassen Werkschema'!R40,"") | R10: =IF('Aanpassen Werkschema'!S40>0,'Aanpassen Werkschema'!S40,"") | S10: =IF('Aanpassen Werkschema'!T40="x","",IF('Aanpassen Werkschema'!N40="v","x",IF(E10="","",IF(E10="x","x")))) | T10: =IF('Aanpassen Werkschema'!U40="x","",IF('Aanpassen Werkschema'!O40="v","x",IF(F10="","",IF(F10="x","x")))) | U10: =IF('Aanpassen Werkschema'!V40="x","",IF('Aanpassen Werkschema'!P40="v","x",IF(G10="","",IF(G10="x","x")))) | V10: =IF('Aanpassen Werkschema'!W40="x","",IF('Aanpassen Werkschema'!Q40="v","x",IF(H10="","",IF(H10="x","x")))) | W10: =IF('Aanpassen Werkschema'!X40="x","",IF('Aanpassen Werkschema'!R40="v","x",IF(I10="","",IF(I10="x","x")))) | X10: =IF('Aanpassen Werkschema'!Y40="x","",IF('Aanpassen Werkschema'!S40="v","x",IF(J10="","",IF(J10="x","x")))) | Y10: =IF('Aanpassen Werkschema'!Z40="x","",IF('Aanpassen Werkschema'!T40="v","x",IF(K10="","",IF(K10="x","x")))) | Z10: =Z9+0.0000000001 | AA10: =IFERROR(IF(C10="",1.1,IF(S10="",1,IF($C10=1,VLOOKUP($B10,'Werkschema - Rekening'!$B$2:$C$46,2,FALSE),IF($C10=2,Instellingen!C$16,IF($C10=3,Instellingen!D$16,IF($C10=4,L10))))+$D10)+$Z10),1.1) | AB10: =IF($B10="","",IFERROR(VLOOKUP($B10,'Werkschema - Rekening'!$B$2:$P$46,3,FALSE),"")) | AC10: =IFERROR(IF(C10="",1.1,IF(T10="",1,IF($C10=1,VLOOKUP($B10,'Werkschema - Rekening'!$B$2:$E$46,4,FALSE),IF($C10=2,Instellingen!E$16,IF($C10=3,Instellingen!F$16,IF($C10=4,M10))))+$D10)+$Z10),1.1) | AD10: =IF($B10="","",IFERROR(VLOOKUP($B10,'Werkschema - Rekening'!$B$2:$P$46,5,FALSE),"")) | AE10: =IFERROR(IF(C10="",1.1,IF(U10="",1,IF($C10=1,VLOOKUP($B10,'Werkschema - Rekening'!$B$2:$G$46,6,FALSE),IF($C10=2,Instellingen!G$16,IF($C10=3,Instellingen!H$16,IF($C10=4,N10))))+$D10)+$Z10),1.1) | AF10: =IF($B10="","",IFERROR(VLOOKUP($B10,'Werkschema - Rekening'!$B$2:$P$46,7,FALSE),"")) | AG10: =IFERROR(IF(C10="",1.1,IF(V10="",1,IF($C10=1,VLOOKUP($B10,'Werkschema - Rekening'!$B$2:$I$46,8,FALSE),IF($C10=2,Instellingen!I$16,IF($C10=3,Instellingen!J$16,IF($C10=4,O10))))+$D10)+$Z10),1.1) | AH10: =IF($B10="","",IFERROR(VLOOKUP($B10,'Werkschema - Rekening'!$B$2:$P$46,9,FALSE),"")) | AI10: =IFERROR(IF(C10="",1.1,IF(W10="",1,IF($C10=1,VLOOKUP($B10,'Werkschema - Rekening'!$B$2:$K$46,10,FALSE),IF($C10=2,Instellingen!K$16,IF($C10=3,Instellingen!L$16,IF($C10=4,P10))))+$D10)+$Z10),1.1) | AJ10: =IF($B10="","",IFERROR(VLOOKUP($B10,'Werkschema - Rekening'!$B$2:$P$46,11,FALSE),"")) | AK10: =IFERROR(IF(C10="",1.1,IF(X10="",1,IF($C10=1,VLOOKUP($B10,'Werkschema - Rekening'!$B$2:$M$46,12,FALSE),IF($C10=2,Instellingen!M$16,IF($C10=3,Instellingen!N$16,IF($C10=4,Q10))))+$D10)+$Z10),1.1) | AL10: =IF($B10="","",IFERROR(VLOOKUP($B10,'Werkschema - Rekening'!$B$2:$P$46,13,FALSE),"")) | AM10: =IFERROR(IF(C10="",1.1,IF(Y10="",1,IF($C10=1,VLOOKUP($B10,'Werkschema - Rekening'!$B$2:$O$46,14,FALSE),IF($C10=2,Instellingen!O$16,IF($C10=3,Instellingen!P$16,IF($C10=4,R10))))+$D10)+$Z10),1.1) | AN10: =IF($B10="","",IFERROR(VLOOKUP($B10,'Werkschema - Rekening'!$B$2:$P$46,15,FALSE),"")) | AO10: =A10 | AP10: =B10
A11: ='Aanpassen Werkschema'!B41 | B11: ='Aanpassen Werkschema'!C41 | C11: =IF('Aanpassen Werkschema'!D41="geplande taak",1,IF('Aanpassen Werkschema'!D41="openingstijd",2,IF('Aanpassen Werkschema'!D41="sluitingstijd",3,IF('Aanpassen Werkschema'!D41="vaste tijd",4,"")))) | D11: ='Aanpassen Werkschema'!E41 | E11: =IF('Aanpassen Werkschema'!F41="v","x","") | F11: =IF('Aanpassen Werkschema'!G41="v","x","") | G11: =IF('Aanpassen Werkschema'!H41="v","x","") | H11: =IF('Aanpassen Werkschema'!I41="v","x","") | I11: =IF('Aanpassen Werkschema'!J41="v","x","") | J11: =IF('Aanpassen Werkschema'!K41="v","x","") | K11: =IF('Aanpassen Werkschema'!L41="v","x","") | L11: =IF('Aanpassen Werkschema'!M41>0,'Aanpassen Werkschema'!M41,"") | M11: =IF('Aanpassen Werkschema'!N41>0,'Aanpassen Werkschema'!N41,"") | N11: =IF('Aanpassen Werkschema'!O41>0,'Aanpassen Werkschema'!O41,"") | O11: =IF('Aanpassen Werkschema'!P41>0,'Aanpassen Werkschema'!P41,"") | P11: =IF('Aanpassen Werkschema'!Q41>0,'Aanpassen Werkschema'!Q41,"") | Q11: =IF('Aanpassen Werkschema'!R41>0,'Aanpassen Werkschema'!R41,"") | R11: =IF('Aanpassen Werkschema'!S41>0,'Aanpassen Werkschema'!S41,"") | S11: =IF('Aanpassen Werkschema'!T41="x","",IF('Aanpassen Werkschema'!N41="v","x",IF(E11="","",IF(E11="x","x")))) | T11: =IF('Aanpassen Werkschema'!U41="x","",IF('Aanpassen Werkschema'!O41="v","x",IF(F11="","",IF(F11="x","x")))) | U11: =IF('Aanpassen Werkschema'!V41="x","",IF('Aanpassen Werkschema'!P41="v","x",IF(G11="","",IF(G11="x","x")))) | V11: =IF('Aanpassen Werkschema'!W41="x","",IF('Aanpassen Werkschema'!Q41="v","x",IF(H11="","",IF(H11="x","x")))) | W11: =IF('Aanpassen Werkschema'!X41="x","",IF('Aanpassen Werkschema'!R41="v","x",IF(I11="","",IF(I11="x","x")))) | X11: =IF('Aanpassen Werkschema'!Y41="x","",IF('Aanpassen Werkschema'!S41="v","x",IF(J11="","",IF(J11="x","x")))) | Y11: =IF('Aanpassen Werkschema'!Z41="x","",IF('Aanpassen Werkschema'!T41="v","x",IF(K11="","",IF(K11="x","x")))) | Z11: =Z10+0.0000000001 | AA11: =IFERROR(IF(C11="",1.1,IF(S11="",1,IF($C11=1,VLOOKUP($B11,'Werkschema - Rekening'!$B$2:$C$46,2,FALSE),IF($C11=2,Instellingen!C$16,IF($C11=3,Instellingen!D$16,IF($C11=4,L11))))+$D11)+$Z11),1.1) | AB11: =IF($B11="","",IFERROR(VLOOKUP($B11,'Werkschema - Rekening'!$B$2:$P$46,3,FALSE),"")) | AC11: =IFERROR(IF(C11="",1.1,IF(T11="",1,IF($C11=1,VLOOKUP($B11,'Werkschema - Rekening'!$B$2:$E$46,4,FALSE),IF($C11=2,Instellingen!E$16,IF($C11=3,Instellingen!F$16,IF($C11=4,M11))))+$D11)+$Z11),1.1) | AD11: =IF($B11="","",IFERROR(VLOOKUP($B11,'Werkschema - Rekening'!$B$2:$P$46,5,FALSE),"")) | AE11: =IFERROR(IF(C11="",1.1,IF(U11="",1,IF($C11=1,VLOOKUP($B11,'Werkschema - Rekening'!$B$2:$G$46,6,FALSE),IF($C11=2,Instellingen!G$16,IF($C11=3,Instellingen!H$16,IF($C11=4,N11))))+$D11)+$Z11),1.1) | AF11: =IF($B11="","",IFERROR(VLOOKUP($B11,'Werkschema - Rekening'!$B$2:$P$46,7,FALSE),"")) | AG11: =IFERROR(IF(C11="",1.1,IF(V11="",1,IF($C11=1,VLOOKUP($B11,'Werkschema - Rekening'!$B$2:$I$46,8,FALSE),IF($C11=2,Instellingen!I$16,IF($C11=3,Instellingen!J$16,IF($C11=4,O11))))+$D11)+$Z11),1.1) | AH11: =IF($B11="","",IFERROR(VLOOKUP($B11,'Werkschema - Rekening'!$B$2:$P$46,9,FALSE),"")) | AI11: =IFERROR(IF(C11="",1.1,IF(W11="",1,IF($C11=1,VLOOKUP($B11,'Werkschema - Rekening'!$B$2:$K$46,10,FALSE),IF($C11=2,Instellingen!K$16,IF($C11=3,Instellingen!L$16,IF($C11=4,P11))))+$D11)+$Z11),1.1) | AJ11: =IF($B11="","",IFERROR(VLOOKUP($B11,'Werkschema - Rekening'!$B$2:$P$46,11,FALSE),"")) | AK11: =IFERROR(IF(C11="",1.1,IF(X11="",1,IF($C11=1,VLOOKUP($B11,'Werkschema - Rekening'!$B$2:$M$46,12,FALSE),IF($C11=2,Instellingen!M$16,IF($C11=3,Instellingen!N$16,IF($C11=4,Q11))))+$D11)+$Z11),1.1) | AL11: =IF($B11="","",IFERROR(VLOOKUP($B11,'Werkschema - Rekening'!$B$2:$P$46,13,FALSE),"")) | AM11: =IFERROR(IF(C11="",1.1,IF(Y11="",1,IF($C11=1,VLOOKUP($B11,'Werkschema - Rekening'!$B$2:$O$46,14,FALSE),IF($C11=2,Instellingen!O$16,IF($C11=3,Instellingen!P$16,IF($C11=4,R11))))+$D11)+$Z11),1.1) | AN11: =IF($B11="","",IFERROR(VLOOKUP($B11,'Werkschema - Rekening'!$B$2:$P$46,15,FALSE),"")) | AO11: =A11 | AP11: =B11
A12: ='Aanpassen Werkschema'!B42 | B12: ='Aanpassen Werkschema'!C42 | C12: =IF('Aanpassen Werkschema'!D42="geplande taak",1,IF('Aanpassen Werkschema'!D42="openingstijd",2,IF('Aanpassen Werkschema'!D42="sluitingstijd",3,IF('Aanpassen Werkschema'!D42="vaste tijd",4,"")))) | D12: ='Aanpassen Werkschema'!E42 | E12: =IF('Aanpassen Werkschema'!F42="v","x","") | F12: =IF('Aanpassen Werkschema'!G42="v","x","") | G12: =IF('Aanpassen Werkschema'!H42="v","x","") | H12: =IF('Aanpassen Werkschema'!I42="v","x","") | I12: =IF('Aanpassen Werkschema'!J42="v","x","") | J12: =IF('Aanpassen Werkschema'!K42="v","x","") | K12: =IF('Aanpassen Werkschema'!L42="v","x","") | L12: =IF('Aanpassen Werkschema'!M42>0,'Aanpassen Werkschema'!M42,"") | M12: =IF('Aanpassen Werkschema'!N42>0,'Aanpassen Werkschema'!N42,"") | N12: =IF('Aanpassen Werkschema'!O42>0,'Aanpassen Werkschema'!O42,"") | O12: =IF('Aanpassen Werkschema'!P42>0,'Aanpassen Werkschema'!P42,"") | P12: =IF('Aanpassen Werkschema'!Q42>0,'Aanpassen Werkschema'!Q42,"") | Q12: =IF('Aanpassen Werkschema'!R42>0,'Aanpassen Werkschema'!R42,"") | R12: =IF('Aanpassen Werkschema'!S42>0,'Aanpassen Werkschema'!S42,"") | S12: =IF('Aanpassen Werkschema'!T42="x","",IF('Aanpassen Werkschema'!N42="v","x",IF(E12="","",IF(E12="x","x")))) | T12: =IF('Aanpassen Werkschema'!U42="x","",IF('Aanpassen Werkschema'!O42="v","x",IF(F12="","",IF(F12="x","x")))) | U12: =IF('Aanpassen Werkschema'!V42="x","",IF('Aanpassen Werkschema'!P42="v","x",IF(G12="","",IF(G12="x","x")))) | V12: =IF('Aanpassen Werkschema'!W42="x","",IF('Aanpassen Werkschema'!Q42="v","x",IF(H12="","",IF(H12="x","x")))) | W12: =IF('Aanpassen Werkschema'!X42="x","",IF('Aanpassen Werkschema'!R42="v","x",IF(I12="","",IF(I12="x","x")))) | X12: =IF('Aanpassen Werkschema'!Y42="x","",IF('Aanpassen Werkschema'!S42="v","x",IF(J12="","",IF(J12="x","x")))) | Y12: =IF('Aanpassen Werkschema'!Z42="x","",IF('Aanpassen Werkschema'!T42="v","x",IF(K12="","",IF(K12="x","x")))) | Z12: =Z11+0.0000000001 | AA12: =IFERROR(IF(C12="",1.1,IF(S12="",1,IF($C12=1,VLOOKUP($B12,'Werkschema - Rekening'!$B$2:$C$46,2,FALSE),IF($C12=2,Instellingen!C$16,IF($C12=3,Instellingen!D$16,IF($C12=4,L12))))+$D12)+$Z12),1.1) | AB12: =IF($B12="","",IFERROR(VLOOKUP($B12,'Werkschema - Rekening'!$B$2:$P$46,3,FALSE),"")) | AC12: =IFERROR(IF(C12="",1.1,IF(T12="",1,IF($C12=1,VLOOKUP($B12,'Werkschema - Rekening'!$B$2:$E$46,4,FALSE),IF($C12=2,Instellingen!E$16,IF($C12=3,Instellingen!F$16,IF($C12=4,M12))))+$D12)+$Z12),1.1) | AD12: =IF($B12="","",IFERROR(VLOOKUP($B12,'Werkschema - Rekening'!$B$2:$P$46,5,FALSE),"")) | AE12: =IFERROR(IF(C12="",1.1,IF(U12="",1,IF($C12=1,VLOOKUP($B12,'Werkschema - Rekening'!$B$2:$G$46,6,FALSE),IF($C12=2,Instellingen!G$16,IF($C12=3,Instellingen!H$16,IF($C12=4,N12))))+$D12)+$Z12),1.1) | AF12: =IF($B12="","",IFERROR(VLOOKUP($B12,'Werkschema - Rekening'!$B$2:$P$46,7,FALSE),"")) | AG12: =IFERROR(IF(C12="",1.1,IF(V12="",1,IF($C12=1,VLOOKUP($B12,'Werkschema - Rekening'!$B$2:$I$46,8,FALSE),IF($C12=2,Instellingen!I$16,IF($C12=3,Instellingen!J$16,IF($C12=4,O12))))+$D12)+$Z12),1.1) | AH12: =IF($B12="","",IFERROR(VLOOKUP($B12,'Werkschema - Rekening'!$B$2:$P$46,9,FALSE),"")) | AI12: =IFERROR(IF(C12="",1.1,IF(W12="",1,IF($C12=1,VLOOKUP($B12,'Werkschema - Rekening'!$B$2:$K$46,10,FALSE),IF($C12=2,Instellingen!K$16,IF($C12=3,Instellingen!L$16,IF($C12=4,P12))))+$D12)+$Z12),1.1) | AJ12: =IF($B12="","",IFERROR(VLOOKUP($B12,'Werkschema - Rekening'!$B$2:$P$46,11,FALSE),"")) | AK12: =IFERROR(IF(C12="",1.1,IF(X12="",1,IF($C12=1,VLOOKUP($B12,'Werkschema - Rekening'!$B$2:$M$46,12,FALSE),IF($C12=2,Instellingen!M$16,IF($C12=3,Instellingen!N$16,IF($C12=4,Q12))))+$D12)+$Z12),1.1) | AL12: =IF($B12="","",IFERROR(VLOOKUP($B12,'Werkschema - Rekening'!$B$2:$P$46,13,FALSE),"")) | AM12: =IFERROR(IF(C12="",1.1,IF(Y12="",1,IF($C12=1,VLOOKUP($B12,'Werkschema - Rekening'!$B$2:$O$46,14,FALSE),IF($C12=2,Instellingen!O$16,IF($C12=3,Instellingen!P$16,IF($C12=4,R12))))+$D12)+$Z12),1.1) | AN12: =IF($B12="","",IFERROR(VLOOKUP($B12,'Werkschema - Rekening'!$B$2:$P$46,15,FALSE),"")) | AO12: =A12 | AP12: =B12
A13: ='Aanpassen Werkschema'!B43 | B13: ='Aanpassen Werkschema'!C43 | C13: =IF('Aanpassen Werkschema'!D43="geplande taak",1,IF('Aanpassen Werkschema'!D43="openingstijd",2,IF('Aanpassen Werkschema'!D43="sluitingstijd",3,IF('Aanpassen Werkschema'!D43="vaste tijd",4,"")))) | D13: ='Aanpassen Werkschema'!E43 | E13: =IF('Aanpassen Werkschema'!F43="v","x","") | F13: =IF('Aanpassen Werkschema'!G43="v","x","") | G13: =IF('Aanpassen Werkschema'!H43="v","x","") | H13: =IF('Aanpassen Werkschema'!I43="v","x","") | I13: =IF('Aanpassen Werkschema'!J43="v","x","") | J13: =IF('Aanpassen Werkschema'!K43="v","x","") | K13: =IF('Aanpassen Werkschema'!L43="v","x","") | L13: =IF('Aanpassen Werkschema'!M43>0,'Aanpassen Werkschema'!M43,"") | M13: =IF('Aanpassen Werkschema'!N43>0,'Aanpassen Werkschema'!N43,"") | N13: =IF('Aanpassen Werkschema'!O43>0,'Aanpassen Werkschema'!O43,"") | O13: =IF('Aanpassen Werkschema'!P43>0,'Aanpassen Werkschema'!P43,"") | P13: =IF('Aanpassen Werkschema'!Q43>0,'Aanpassen Werkschema'!Q43,"") | Q13: =IF('Aanpassen Werkschema'!R43>0,'Aanpassen Werkschema'!R43,"") | R13: =IF('Aanpassen Werkschema'!S43>0,'Aanpassen Werkschema'!S43,"") | S13: =IF('Aanpassen Werkschema'!T43="x","",IF('Aanpassen Werkschema'!N43="v","x",IF(E13="","",IF(E13="x","x")))) | T13: =IF('Aanpassen Werkschema'!U43="x","",IF('Aanpassen Werkschema'!O43="v","x",IF(F13="","",IF(F13="x","x")))) | U13: =IF('Aanpassen Werkschema'!V43="x","",IF('Aanpassen Werkschema'!P43="v","x",IF(G13="","",IF(G13="x","x")))) | V13: =IF('Aanpassen Werkschema'!W43="x","",IF('Aanpassen Werkschema'!Q43="v","x",IF(H13="","",IF(H13="x","x")))) | W13: =IF('Aanpassen Werkschema'!X43="x","",IF('Aanpassen Werkschema'!R43="v","x",IF(I13="","",IF(I13="x","x")))) | X13: =IF('Aanpassen Werkschema'!Y43="x","",IF('Aanpassen Werkschema'!S43="v","x",IF(J13="","",IF(J13="x","x")))) | Y13: =IF('Aanpassen Werkschema'!Z43="x","",IF('Aanpassen Werkschema'!T43="v","x",IF(K13="","",IF(K13="x","x")))) | Z13: =Z12+0.0000000001 | AA13: =IFERROR(IF(C13="",1.1,IF(S13="",1,IF($C13=1,VLOOKUP($B13,'Werkschema - Rekening'!$B$2:$C$46,2,FALSE),IF($C13=2,Instellingen!C$16,IF($C13=3,Instellingen!D$16,IF($C13=4,L13))))+$D13)+$Z13),1.1) | AB13: =IF($B13="","",IFERROR(VLOOKUP($B13,'Werkschema - Rekening'!$B$2:$P$46,3,FALSE),"")) | AC13: =IFERROR(IF(C13="",1.1,IF(T13="",1,IF($C13=1,VLOOKUP($B13,'Werkschema - Rekening'!$B$2:$E$46,4,FALSE),IF($C13=2,Instellingen!E$16,IF($C13=3,Instellingen!F$16,IF($C13=4,M13))))+$D13)+$Z13),1.1) | AD13: =IF($B13="","",IFERROR(VLOOKUP($B13,'Werkschema - Rekening'!$B$2:$P$46,5,FALSE),"")) | AE13: =IFERROR(IF(C13="",1.1,IF(U13="",1,IF($C13=1,VLOOKUP($B13,'Werkschema - Rekening'!$B$2:$G$46,6,FALSE),IF($C13=2,Instellingen!G$16,IF($C13=3,Instellingen!H$16,IF($C13=4,N13))))+$D13)+$Z13),1.1) | AF13: =IF($B13="","",IFERROR(VLOOKUP($B13,'Werkschema - Rekening'!$B$2:$P$46,7,FALSE),"")) | AG13: =IFERROR(IF(C13="",1.1,IF(V13="",1,IF($C13=1,VLOOKUP($B13,'Werkschema - Rekening'!$B$2:$I$46,8,FALSE),IF($C13=2,Instellingen!I$16,IF($C13=3,Instellingen!J$16,IF($C13=4,O13))))+$D13)+$Z13),1.1) | AH13: =IF($B13="","",IFERROR(VLOOKUP($B13,'Werkschema - Rekening'!$B$2:$P$46,9,FALSE),"")) | AI13: =IFERROR(IF(C13="",1.1,IF(W13="",1,IF($C13=1,VLOOKUP($B13,'Werkschema - Rekening'!$B$2:$K$46,10,FALSE),IF($C13=2,Instellingen!K$16,IF($C13=3,Instellingen!L$16,IF($C13=4,P13))))+$D13)+$Z13),1.1) | AJ13: =IF($B13="","",IFERROR(VLOOKUP($B13,'Werkschema - Rekening'!$B$2:$P$46,11,FALSE),"")) | AK13: =IFERROR(IF(C13="",1.1,IF(X13="",1,IF($C13=1,VLOOKUP($B13,'Werkschema - Rekening'!$B$2:$M$46,12,FALSE),IF($C13=2,Instellingen!M$16,IF($C13=3,Instellingen!N$16,IF($C13=4,Q13))))+$D13)+$Z13),1.1) | AL13: =IF($B13="","",IFERROR(VLOOKUP($B13,'Werkschema - Rekening'!$B$2:$P$46,13,FALSE),"")) | AM13: =IFERROR(IF(C13="",1.1,IF(Y13="",1,IF($C13=1,VLOOKUP($B13,'Werkschema - Rekening'!$B$2:$O$46,14,FALSE),IF($C13=2,Instellingen!O$16,IF($C13=3,Instellingen!P$16,IF($C13=4,R13))))+$D13)+$Z13),1.1) | AN13: =IF($B13="","",IFERROR(VLOOKUP($B13,'Werkschema - Rekening'!$B$2:$P$46,15,FALSE),"")) | AO13: =A13 | AP13: =B13
A14: ='Aanpassen Werkschema'!B44 | B14: ='Aanpassen Werkschema'!C44 | C14: =IF('Aanpassen Werkschema'!D44="geplande taak",1,IF('Aanpassen Werkschema'!D44="openingstijd",2,IF('Aanpassen Werkschema'!D44="sluitingstijd",3,IF('Aanpassen Werkschema'!D44="vaste tijd",4,"")))) | D14: ='Aanpassen Werkschema'!E44 | E14: =IF('Aanpassen Werkschema'!F44="v","x","") | F14: =IF('Aanpassen Werkschema'!G44="v","x","") | G14: =IF('Aanpassen Werkschema'!H44="v","x","") | H14: =IF('Aanpassen Werkschema'!I44="v","x","") | I14: =IF('Aanpassen Werkschema'!J44="v","x","") | J14: =IF('Aanpassen Werkschema'!K44="v","x","") | K14: =IF('Aanpassen Werkschema'!L44="v","x","") | L14: =IF('Aanpassen Werkschema'!M44>0,'Aanpassen Werkschema'!M44,"") | M14: =IF('Aanpassen Werkschema'!N44>0,'Aanpassen Werkschema'!N44,"") | N14: =IF('Aanpassen Werkschema'!O44>0,'Aanpassen Werkschema'!O44,"") | O14: =IF('Aanpassen Werkschema'!P44>0,'Aanpassen Werkschema'!P44,"") | P14: =IF('Aanpassen Werkschema'!Q44>0,'Aanpassen Werkschema'!Q44,"") | Q14: =IF('Aanpassen Werkschema'!R44>0,'Aanpassen Werkschema'!R44,"") | R14: =IF('Aanpassen Werkschema'!S44>0,'Aanpassen Werkschema'!S44,"") | S14: =IF('Aanpassen Werkschema'!T44="x","",IF('Aanpassen Werkschema'!N44="v","x",IF(E14="","",IF(E14="x","x")))) | T14: =IF('Aanpassen Werkschema'!U44="x","",IF('Aanpassen Werkschema'!O44="v","x",IF(F14="","",IF(F14="x","x")))) | U14: =IF('Aanpassen Werkschema'!V44="x","",IF('Aanpassen Werkschema'!P44="v","x",IF(G14="","",IF(G14="x","x")))) | V14: =IF('Aanpassen Werkschema'!W44="x","",IF('Aanpassen Werkschema'!Q44="v","x",IF(H14="","",IF(H14="x","x")))) | W14: =IF('Aanpassen Werkschema'!X44="x","",IF('Aanpassen Werkschema'!R44="v","x",IF(I14="","",IF(I14="x","x")))) | X14: =IF('Aanpassen Werkschema'!Y44="x","",IF('Aanpassen Werkschema'!S44="v","x",IF(J14="","",IF(J14="x","x")))) | Y14: =IF('Aanpassen Werkschema'!Z44="x","",IF('Aanpassen Werkschema'!T44="v","x",IF(K14="","",IF(K14="x","x")))) | Z14: =Z13+0.0000000001 | AA14: =IFERROR(IF(C14="",1.1,IF(S14="",1,IF($C14=1,VLOOKUP($B14,'Werkschema - Rekening'!$B$2:$C$46,2,FALSE),IF($C14=2,Instellingen!C$16,IF($C14=3,Instellingen!D$16,IF($C14=4,L14))))+$D14)+$Z14),1.1) | AB14: =IF($B14="","",IFERROR(VLOOKUP($B14,'Werkschema - Rekening'!$B$2:$P$46,3,FALSE),"")) | AC14: =IFERROR(IF(C14="",1.1,IF(T14="",1,IF($C14=1,VLOOKUP($B14,'Werkschema - Rekening'!$B$2:$E$46,4,FALSE),IF($C14=2,Instellingen!E$16,IF($C14=3,Instellingen!F$16,IF($C14=4,M14))))+$D14)+$Z14),1.1) | AD14: =IF($B14="","",IFERROR(VLOOKUP($B14,'Werkschema - Rekening'!$B$2:$P$46,5,FALSE),"")) | AE14: =IFERROR(IF(C14="",1.1,IF(U14="",1,IF($C14=1,VLOOKUP($B14,'Werkschema - Rekening'!$B$2:$G$46,6,FALSE),IF($C14=2,Instellingen!G$16,IF($C14=3,Instellingen!H$16,IF($C14=4,N14))))+$D14)+$Z14),1.1) | AF14: =IF($B14="","",IFERROR(VLOOKUP($B14,'Werkschema - Rekening'!$B$2:$P$46,7,FALSE),"")) | AG14: =IFERROR(IF(C14="",1.1,IF(V14="",1,IF($C14=1,VLOOKUP($B14,'Werkschema - Rekening'!$B$2:$I$46,8,FALSE),IF($C14=2,Instellingen!I$16,IF($C14=3,Instellingen!J$16,IF($C14=4,O14))))+$D14)+$Z14),1.1) | AH14: =IF($B14="","",IFERROR(VLOOKUP($B14,'Werkschema - Rekening'!$B$2:$P$46,9,FALSE),"")) | AI14: =IFERROR(IF(C14="",1.1,IF(W14="",1,IF($C14=1,VLOOKUP($B14,'Werkschema - Rekening'!$B$2:$K$46,10,FALSE),IF($C14=2,Instellingen!K$16,IF($C14=3,Instellingen!L$16,IF($C14=4,P14))))+$D14)+$Z14),1.1) | AJ14: =IF($B14="","",IFERROR(VLOOKUP($B14,'Werkschema - Rekening'!$B$2:$P$46,11,FALSE),"")) | AK14: =IFERROR(IF(C14="",1.1,IF(X14="",1,IF($C14=1,VLOOKUP($B14,'Werkschema - Rekening'!$B$2:$M$46,12,FALSE),IF($C14=2,Instellingen!M$16,IF($C14=3,Instellingen!N$16,IF($C14=4,Q14))))+$D14)+$Z14),1.1) | AL14: =IF($B14="","",IFERROR(VLOOKUP($B14,'Werkschema - Rekening'!$B$2:$P$46,13,FALSE),"")) | AM14: =IFERROR(IF(C14="",1.1,IF(Y14="",1,IF($C14=1,VLOOKUP($B14,'Werkschema - Rekening'!$B$2:$O$46,14,FALSE),IF($C14=2,Instellingen!O$16,IF($C14=3,Instellingen!P$16,IF($C14=4,R14))))+$D14)+$Z14),1.1) | AN14: =IF($B14="","",IFERROR(VLOOKUP($B14,'Werkschema - Rekening'!$B$2:$P$46,15,FALSE),"")) | AO14: =A14 | AP14: =B14
A15: ='Aanpassen Werkschema'!B45 | B15: ='Aanpassen Werkschema'!C45 | C15: =IF('Aanpassen Werkschema'!D45="geplande taak",1,IF('Aanpassen Werkschema'!D45="openingstijd",2,IF('Aanpassen Werkschema'!D45="sluitingstijd",3,IF('Aanpassen Werkschema'!D45="vaste tijd",4,"")))) | D15: ='Aanpassen Werkschema'!E45 | E15: =IF('Aanpassen Werkschema'!F45="v","x","") | F15: =IF('Aanpassen Werkschema'!G45="v","x","") | G15: =IF('Aanpassen Werkschema'!H45="v","x","") | H15: =IF('Aanpassen Werkschema'!I45="v","x","") | I15: =IF('Aanpassen Werkschema'!J45="v","x","") | J15: =IF('Aanpassen Werkschema'!K45="v","x","") | K15: =IF('Aanpassen Werkschema'!L45="v","x","") | L15: =IF('Aanpassen Werkschema'!M45>0,'Aanpassen Werkschema'!M45,"") | M15: =IF('Aanpassen Werkschema'!N45>0,'Aanpassen Werkschema'!N45,"") | N15: =IF('Aanpassen Werkschema'!O45>0,'Aanpassen Werkschema'!O45,"") | O15: =IF('Aanpassen Werkschema'!P45>0,'Aanpassen Werkschema'!P45,"") | P15: =IF('Aanpassen Werkschema'!Q45>0,'Aanpassen Werkschema'!Q45,"") | Q15: =IF('Aanpassen Werkschema'!R45>0,'Aanpassen Werkschema'!R45,"") | R15: =IF('Aanpassen Werkschema'!S45>0,'Aanpassen Werkschema'!S45,"") | S15: =IF('Aanpassen Werkschema'!T45="x","",IF('Aanpassen Werkschema'!N45="v","x",IF(E15="","",IF(E15="x","x")))) | T15: =IF('Aanpassen Werkschema'!U45="x","",IF('Aanpassen Werkschema'!O45="v","x",IF(F15="","",IF(F15="x","x")))) | U15: =IF('Aanpassen Werkschema'!V45="x","",IF('Aanpassen Werkschema'!P45="v","x",IF(G15="","",IF(G15="x","x")))) | V15: =IF('Aanpassen Werkschema'!W45="x","",IF('Aanpassen Werkschema'!Q45="v","x",IF(H15="","",IF(H15="x","x")))) | W15: =IF('Aanpassen Werkschema'!X45="x","",IF('Aanpassen Werkschema'!R45="v","x",IF(I15="","",IF(I15="x","x")))) | X15: =IF('Aanpassen Werkschema'!Y45="x","",IF('Aanpassen Werkschema'!S45="v","x",IF(J15="","",IF(J15="x","x")))) | Y15: =IF('Aanpassen Werkschema'!Z45="x","",IF('Aanpassen Werkschema'!T45="v","x",IF(K15="","",IF(K15="x","x")))) | Z15: =Z14+0.0000000001 | AA15: =IFERROR(IF(C15="",1.1,IF(S15="",1,IF($C15=1,VLOOKUP($B15,'Werkschema - Rekening'!$B$2:$C$46,2,FALSE),IF($C15=2,Instellingen!C$16,IF($C15=3,Instellingen!D$16,IF($C15=4,L15))))+$D15)+$Z15),1.1) | AB15: =IF($B15="","",IFERROR(VLOOKUP($B15,'Werkschema - Rekening'!$B$2:$P$46,3,FALSE),"")) | AC15: =IFERROR(IF(C15="",1.1,IF(T15="",1,IF($C15=1,VLOOKUP($B15,'Werkschema - Rekening'!$B$2:$E$46,4,FALSE),IF($C15=2,Instellingen!E$16,IF($C15=3,Instellingen!F$16,IF($C15=4,M15))))+$D15)+$Z15),1.1) | AD15: =IF($B15="","",IFERROR(VLOOKUP($B15,'Werkschema - Rekening'!$B$2:$P$46,5,FALSE),"")) | AE15: =IFERROR(IF(C15="",1.1,IF(U15="",1,IF($C15=1,VLOOKUP($B15,'Werkschema - Rekening'!$B$2:$G$46,6,FALSE),IF($C15=2,Instellingen!G$16,IF($C15=3,Instellingen!H$16,IF($C15=4,N15))))+$D15)+$Z15),1.1) | AF15: =IF($B15="","",IFERROR(VLOOKUP($B15,'Werkschema - Rekening'!$B$2:$P$46,7,FALSE),"")) | AG15: =IFERROR(IF(C15="",1.1,IF(V15="",1,IF($C15=1,VLOOKUP($B15,'Werkschema - Rekening'!$B$2:$I$46,8,FALSE),IF($C15=2,Instellingen!I$16,IF($C15=3,Instellingen!J$16,IF($C15=4,O15))))+$D15)+$Z15),1.1) | AH15: =IF($B15="","",IFERROR(VLOOKUP($B15,'Werkschema - Rekening'!$B$2:$P$46,9,FALSE),"")) | AI15: =IFERROR(IF(C15="",1.1,IF(W15="",1,IF($C15=1,VLOOKUP($B15,'Werkschema - Rekening'!$B$2:$K$46,10,FALSE),IF($C15=2,Instellingen!K$16,IF($C15=3,Instellingen!L$16,IF($C15=4,P15))))+$D15)+$Z15),1.1) | AJ15: =IF($B15="","",IFERROR(VLOOKUP($B15,'Werkschema - Rekening'!$B$2:$P$46,11,FALSE),"")) | AK15: =IFERROR(IF(C15="",1.1,IF(X15="",1,IF($C15=1,VLOOKUP($B15,'Werkschema - Rekening'!$B$2:$M$46,12,FALSE),IF($C15=2,Instellingen!M$16,IF($C15=3,Instellingen!N$16,IF($C15=4,Q15))))+$D15)+$Z15),1.1) | AL15: =IF($B15="","",IFERROR(VLOOKUP($B15,'Werkschema - Rekening'!$B$2:$P$46,13,FALSE),"")) | AM15: =IFERROR(IF(C15="",1.1,IF(Y15="",1,IF($C15=1,VLOOKUP($B15,'Werkschema - Rekening'!$B$2:$O$46,14,FALSE),IF($C15=2,Instellingen!O$16,IF($C15=3,Instellingen!P$16,IF($C15=4,R15))))+$D15)+$Z15),1.1) | AN15: =IF($B15="","",IFERROR(VLOOKUP($B15,'Werkschema - Rekening'!$B$2:$P$46,15,FALSE),"")) | AO15: =A15 | AP15: =B15
... A31: ='Aanpassen Werkschema'!B61 | B31: ='Aanpassen Werkschema'!C61 | C31: =IF('Aanpassen Werkschema'!D61="geplande taak",1,IF('Aanpassen Werkschema'!D61="openingstijd",2,IF('Aanpassen Werkschema'!D61="sluitingstijd",3,IF('Aanpassen Werkschema'!D61="vaste tijd",4,"")))) | D31: ='Aanpassen Werkschema'!E61 | E31: =IF('Aanpassen Werkschema'!F61="v","x","") | F31: =IF('Aanpassen Werkschema'!G61="v","x","") | G31: =IF('Aanpassen Werkschema'!H61="v","x","") | H31: =IF('Aanpassen Werkschema'!I61="v","x","") | I31: =IF('Aanpassen Werkschema'!J61="v","x","") | J31: =IF('Aanpassen Werkschema'!K61="v","x","") | K31: =IF('Aanpassen Werkschema'!L61="v","x","") | L31: =IF('Aanpassen Werkschema'!M61>0,'Aanpassen Werkschema'!M61,"") | M31: =IF('Aanpassen Werkschema'!N61>0,'Aanpassen Werkschema'!N61,"") | N31: =IF('Aanpassen Werkschema'!O61>0,'Aanpassen Werkschema'!O61,"") | O31: =IF('Aanpassen Werkschema'!P61>0,'Aanpassen Werkschema'!P61,"") | P31: =IF('Aanpassen Werkschema'!Q61>0,'Aanpassen Werkschema'!Q61,"") | Q31: =IF('Aanpassen Werkschema'!R61>0,'Aanpassen Werkschema'!R61,"") | R31: =IF('Aanpassen Werkschema'!S61>0,'Aanpassen Werkschema'!S61,"") | S31: =IF('Aanpassen Werkschema'!T61="x","",IF('Aanpassen Werkschema'!N61="v","x",IF(E31="","",IF(E31="x","x")))) | T31: =IF('Aanpassen Werkschema'!U61="x","",IF('Aanpassen Werkschema'!O61="v","x",IF(F31="","",IF(F31="x","x")))) | U31: =IF('Aanpassen Werkschema'!V61="x","",IF('Aanpassen Werkschema'!P61="v","x",IF(G31="","",IF(G31="x","x")))) | V31: =IF('Aanpassen Werkschema'!W61="x","",IF('Aanpassen Werkschema'!Q61="v","x",IF(H31="","",IF(H31="x","x")))) | W31: =IF('Aanpassen Werkschema'!X61="x","",IF('Aanpassen Werkschema'!R61="v","x",IF(I31="","",IF(I31="x","x")))) | X31: =IF('Aanpassen Werkschema'!Y61="x","",IF('Aanpassen Werkschema'!S61="v","x",IF(J31="","",IF(J31="x","x")))) | Y31: =IF('Aanpassen Werkschema'!Z61="x","",IF('Aanpassen Werkschema'!T61="v","x",IF(K31="","",IF(K31="x","x")))) | Z31: =Z30+0.0000000001 | AA31: =IFERROR(IF(C31="",1.1,IF(S31="",1,IF($C31=1,VLOOKUP($B31,'Werkschema - Rekening'!$B$2:$C$46,2,FALSE),IF($C31=2,Instellingen!C$16,IF($C31=3,Instellingen!D$16,IF($C31=4,L31))))+$D31)+$Z31),1.1) | AB31: =IF($B31="","",IFERROR(VLOOKUP($B31,'Werkschema - Rekening'!$B$2:$P$46,3,FALSE),"")) | AC31: =IFERROR(IF(C31="",1.1,IF(T31="",1,IF($C31=1,VLOOKUP($B31,'Werkschema - Rekening'!$B$2:$E$46,4,FALSE),IF($C31=2,Instellingen!E$16,IF($C31=3,Instellingen!F$16,IF($C31=4,M31))))+$D31)+$Z31),1.1) | AD31: =IF($B31="","",IFERROR(VLOOKUP($B31,'Werkschema - Rekening'!$B$2:$P$46,5,FALSE),"")) | AE31: =IFERROR(IF(C31="",1.1,IF(U31="",1,IF($C31=1,VLOOKUP($B31,'Werkschema - Rekening'!$B$2:$G$46,6,FALSE),IF($C31=2,Instellingen!G$16,IF($C31=3,Instellingen!H$16,IF($C31=4,N31))))+$D31)+$Z31),1.1) | AF31: =IF($B31="","",IFERROR(VLOOKUP($B31,'Werkschema - Rekening'!$B$2:$P$46,7,FALSE),"")) | AG31: =IFERROR(IF(C31="",1.1,IF(V31="",1,IF($C31=1,VLOOKUP($B31,'Werkschema - Rekening'!$B$2:$I$46,8,FALSE),IF($C31=2,Instellingen!I$16,IF($C31=3,Instellingen!J$16,IF($C31=4,O31))))+$D31)+$Z31),1.1) | AH31: =IF($B31="","",IFERROR(VLOOKUP($B31,'Werkschema - Rekening'!$B$2:$P$46,9,FALSE),"")) | AI31: =IFERROR(IF(C31="",1.1,IF(W31="",1,IF($C31=1,VLOOKUP($B31,'Werkschema - Rekening'!$B$2:$K$46,10,FALSE),IF($C31=2,Instellingen!K$16,IF($C31=3,Instellingen!L$16,IF($C31=4,P31))))+$D31)+$Z31),1.1) | AJ31: =IF($B31="","",IFERROR(VLOOKUP($B31,'Werkschema - Rekening'!$B$2:$P$46,11,FALSE),"")) | AK31: =IFERROR(IF(C31="",1.1,IF(X31="",1,IF($C31=1,VLOOKUP($B31,'Werkschema - Rekening'!$B$2:$M$46,12,FALSE),IF($C31=2,Instellingen!M$16,IF($C31=3,Instellingen!N$16,IF($C31=4,Q31))))+$D31)+$Z31),1.1) | AL31: =IF($B31="","",IFERROR(VLOOKUP($B31,'Werkschema - Rekening'!$B$2:$P$46,13,FALSE),"")) | AM31: =IFERROR(IF(C31="",1.1,IF(Y31="",1,IF($C31=1,VLOOKUP($B31,'Werkschema - Rekening'!$B$2:$O$46,14,FALSE),IF($C31=2,Instellingen!O$16,IF($C31=3,Instellingen!P$16,IF($C31=4,R31))))+$D31)+$Z31),1.1) | AN31: =IF($B31="","",IFERROR(VLOOKUP($B31,'Werkschema - Rekening'!$B$2:$P$46,15,FALSE),"")) | AO31: =A31 | AP31: =B31
